If we have an error inside of async function, we can't handle it via try catch, that's why we have catch() method for async functions. 

```js
Promise.reject(4).catch((err) => {
  console.log(err);
});
```
In browser if we throw an error and don't handle it, we will have silent error, but in Node.js we will get UnhandledPromiseRejection error. 

```js

Promise.resolve(4)
  .then(() => {
    throw new Error();
  })
  .catch((err) => {
    console.log(err);
    return err;
  })
  .then((res) => {
    console.log(res, 1);
  })
  .catch((err) => {
    console.log(err, 2);
  });
```

If you haven't handled promise rejection, it could spell your application might be leaving a critical error unattended to.


### Nested promises
```js
Promise.resolve(4)
  .then(() => {
    Promise.reject(5).catch((err) => {
      console.log(err);
    });

    return 2;
  })
  .catch((err) => {
    console.log(err, 1);
    return err;
  })
  .then((res) => {
    console.log(res, 2);
  })
  .catch((err) => {
    console.log(err, 3);
  });

```
We catch something for each promise